Workbook

Sheet 1. README
A1: KNNO Coffee — Phase Financials & Risk Workbook
A2: v2 · 2026-05-11 · Phase 1 prep list aligned with user-supplied equipment + certs requirements
A4: How to use this workbook
A5: Color convention | B5: BLUE = inputs you change · BLACK = formulas · GREEN = cross-sheet references · YELLOW background = key assumptions to revisit
A6: Update sequence | B6: 1. Review Phase 1 Budget (line items now mirror your prep list). 2. Update Phase 1 Revenue assumptions. 3. After carboot pop-ups, enter Decision Gate actuals. 4. Read decision flag.
A7: Currency | B7: All figures in RM (Malaysian Ringgit) unless stated.
A8: What changed in v2 | B8: Sub-phase 1B rewritten to match your actual prep list (proper coffee cart with water pump+sink, 4 drippers, brand banner, etc.). New Sub-phase 1D for certs (typhoid jab, food handling permit, car boot permit). Phase 2 capex reduced where Phase 1 already covers (cart, brand identity).
A10: Sheet | B10: Purpose
A11: 1. README | B11: This sheet
A12: 2. P1 Budget | B12: Indonesia R&D + Carboot prep (your prep list) + Carboot ops + Certs. Min/Base/Max ranges.
A13: 3. P1 Revenue | B13: Carboot pop-up revenue model. 3 scenarios (Bear/Base/Bull). 4 pop-ups.
A14: 4. P1 Net Cash | B14: Net cash after Phase 1 = revenue − cost. Reusable equipment carry-over.
A15: 5. P2 Capex | B15: Build phase capex (reduced — cart and brand identity already in Phase 1).
A16: 6. Combined Capex | B16: Master view: P1 + P2 vs RM 15K budget. Trim options.
A17: 7. Decision Gate | B17: P1→P2 weighted scoring. 10 criteria. Auto-classifies GO / HOLD / NO-GO.
... A23: Linked vault docs | B23: 08-Action Plan & Timeline.md · 09-Financial Projections (Conservative).md · 07-Risks & Failure Modes.md · 02-Market Analysis & Validation.md · 06-Suppliers & Co-Roasting.md

Sheet 2. P1 Budget
A1: PHASE 1 BUDGET — Indonesia R&D + Carboot Validation (v2 — your prep list)
A2: All RM. Min/Base/Max are honest range estimates. "Reusable" = carries into Phase 2 (reduces P2 capex).
A4: Sub-phase 1A — F1 to Indonesia (~10–14 days)
A5: # | B5: Line item | C5: Min | D5: Base | E5: Max | F5: Reusable? | G5: Notes
A6: 1A.1 | B6: Flight to Bandung (return, AirAsia/MAS economy) | C6: 800 | D6: 1000 | E6: 1200 | F6: No | G6: Book 4+ weeks ahead
A7: 1A.2 | B7: Accommodation 7–10 nights | C7: 700 | D7: 950 | E7: 1200 | F7: No | G7: Guesthouse / mid Airbnb
A8: 1A.3 | B8: Roastery rental fees (sample roaster) | C8: 200 | D8: 350 | E8: 500 | F8: No | G8: Producer site = often free
A9: 1A.4 | B9: Green coffee bought in Indonesia (8–12 kg) | C9: 800 | D9: 1150 | E9: 1500 | F9: Partial | G9: 5–8 kg flows to Phase 2 production
A10: 1A.5 | B10: Local transport (Grab, Gojek, intercity) | C10: 200 | D10: 300 | E10: 450 | F10: No | G10: 10–14 days of movement
A11: 1A.6 | B11: Food & per diem (~RM 60–80/day × 10 days) | C11: 400 | D11: 600 | E11: 800 | F11: No | G11: Local meals
A12: 1A.7 | B12: Vacuum bags + import declaration prep | C12: 50 | D12: 100 | E12: 150 | F12: No | G12: Packaging for transit
A13: 1A.8 | B13: Contingency (10% of itemised) | C13: =ROUND(0.1*SUM(C6:C12),0) -> 315 | D13: =ROUND(0.1*SUM(D6:D12),0) -> 445 | E13: =ROUND(0.1*SUM(E6:E12),0) -> 580 | F13: No | G13: Standard 10% buffer
B14: Sub-phase 1A subtotal | C14: =SUM(C6:C13) -> 3465 | D14: =SUM(D6:D13) -> 4895 | E14: =SUM(E6:E13) -> 6380
A16: Sub-phase 1B — Coffee Cart + Equipment Prep (your prep list)
A17: # | B17: Line item | C17: Min | D17: Base | E17: Max | F17: Reusable? | G17: Notes
A18: 1B.1 | B18: Coffee cart with water pump + sink (mobile, manual-brew config) | C18: 1500 | D18: 2200 | E18: 3000 | F18: Yes | G18: Carries into Phase 2; may need finish/upgrade in P2
A19: 1B.2 | B19: Glassware (cupping/serving glasses, demitasses, tasters) | C19: 150 | D19: 220 | E19: 300 | F19: Yes | G19: For carboot cupping moments + flight serves
A20: 1B.3 | B20: Paper / plastic cups + lids (initial 250 units) | C20: 80 | D20: 120 | E20: 180 | F20: Partial | G20: Generic at first; branded sleeves over the top
A21: 1B.4 | B21: Hand grinder (Comandante or equivalent) | C21: 700 | D21: 800 | E21: 950 | F21: Yes | G21: Reusable as filter/backup grinder in Phase 2
A22: 1B.5 | B22: V60 drippers ×3 — Hario Switch where possible | C22: 450 | D22: 520 | E22: 600 | F22: Yes | G22: Switches enable hybrid immersion-percolation; speeds parallel service
A23: 1B.6 | B23: Origami dripper ×1 (4th total dripper) | C23: 200 | D23: 250 | E23: 320 | F23: Yes | G23: Different geometry/profile vs V60s
A24: 1B.7 | B24: V60 + Origami servers/jugs (×4) | C24: 120 | D24: 180 | E24: 260 | F24: Yes | G24: Hario range server or equivalent
A25: 1B.8 | B25: Brewista kettle (electric gooseneck) | C25: 380 | D25: 480 | E25: 600 | F25: Yes | G25: Variable-temp model preferred
A26: 1B.9 | B26: Paper filters (V60 02 + Origami, initial stock) | C26: 80 | D26: 120 | E26: 180 | F26: No | G26: Replenished per pop-up
A27: 1B.10 | B27: Brewing scales ×2 (Acaia / Hario) | C27: 280 | D27: 400 | E27: 700 | F27: Yes | G27: Two scales for parallel brewing
A28: 1B.11 | B28: Brand identity full delivery (logo + ID system v1, full not deposit) | C28: 1000 | D28: 1500 | E28: 2200 | F28: Yes | G28: Required so banner + lot cards carry KNNO design
A29: 1B.12 | B29: Branded banner (vinyl, with brandkit + design) | C29: 250 | D29: 380 | E29: 550 | F29: Yes | G29: Vinyl banner ~2m×1m, retractable stand if possible
... A33: 1B.16 | B33: IG poll/V2 + V5 small ad amplification | C33: 0 | D33: 50 | E33: 150 | F33: No | G33: Optional small boost
A34: 1B.17 | B34: Contingency (10% of itemised) | C34: =ROUND(0.1*SUM(C18:C33),0) -> 565 | D34: =ROUND(0.1*SUM(D18:D33),0) -> 796 | E34: =ROUND(0.1*SUM(E18:E33),0) -> 1110 | F34: No | G34: Standard 10% buffer
B35: Sub-phase 1B subtotal | C35: =SUM(C18:C34) -> 6215 | D35: =SUM(D18:D34) -> 8756 | E35: =SUM(E18:E34) -> 12210
A37: Sub-phase 1C — Carboot Validation Pop-Ups (4 events, ops-only)
A38: # | B38: Line item | C38: Min | D38: Base | E38: Max | F38: Reusable? | G38: Notes
A39: 1C.1 | B39: Venue fees (4 events; mostly free, 1–2 paid) | C39: 0 | D39: 200 | E39: 400 | F39: No | G39: Friend cafes free; small market sublet RM 100–200
A40: 1C.2 | B40: Per-event consumables: extra cups, lids, sleeves (4 events) | C40: 240 | D40: 320 | E40: 400 | F40: No | G40: Beyond initial stock in 1B.3
A41: 1C.3 | B41: Milk + oat milk (4 events) | C41: 80 | D41: 120 | E41: 180 | F41: No | G41: ~1L per event, whole + oat
A42: 1C.4 | B42: Transport / Grab / fuel (4 events) | C42: 120 | D42: 200 | E42: 320 | F42: No | G42: Cart kit transport
A43: 1C.5 | B43: Sundries (napkins, sanitiser, bin liners, water cups) | C43: 100 | D43: 160 | E43: 240 | F43: No | G43: Bulk-buy once
A44: 1C.6 | B44: Validation V1 reward (30 friends taste test) | C44: 0 | D44: 80 | E44: 150 | F44: No | G44: Optional thank-you
B45: Sub-phase 1C subtotal | C45: =SUM(C39:C44) -> 540 | D45: =SUM(D39:D44) -> 1080 | E45: =SUM(E39:E44) -> 1690
A47: Sub-phase 1D — Certs & Permits (your prep list)
...

Sheet 3. P1 Revenue
A1: PHASE 1 REVENUE — Carboot Pop-Ups (4 events)
A2: Per-event scenarios. BLUE = inputs.
A4: Per-Pop-Up Assumptions
A5: # | B5: Variable | C5: Bear | D5: Base | E5: Bull | F5: Notes
A6: R.1 | B6: Cups served per pop-up | C6: 25 | D6: 40 | E6: 65 | F6: Bear=friends only · Base=walk-up converts · Bull=well-attended venue
A7: R.2 | B7: Avg ticket price (RM/cup) | C7: 12 | D7: 13 | E7: 14 | F7: Carboot pricing — slightly under Phase 4 menu
A8: R.3 | B8: Bag sales per pop-up (units) | C8: 0 | D8: 1 | E8: 3 | F8: Pre-bagged 100g samplers
A9: R.4 | B9: Avg bag price (RM) | C9: 30 | D9: 35 | E9: 40 | F9: Lo-fi 100g sampler
A10: R.5 | B10: Tip / extra contribution (avg RM/cup) | C10: 0 | D10: 0.5 | E10: 1.5 | F10: Optional tip jar
B12: Per pop-up revenue | C12: =C6*C7+C8*C9+C6*C10 -> 300 | D12: =D6*D7+D8*D9+D6*D10 -> 575 | E12: =E6*E7+E8*E9+E6*E10 -> 1127.5
A14: R.6 | B14: Number of pop-ups in Phase 1 | C14: 4 | D14: 4 | E14: 4 | F14: Per action plan §4 sub-phase 1C
B16: PHASE 1 TOTAL REVENUE (all 4 pop-ups) | C16: =C12*C14 -> 1200 | D16: =D12*D14 -> 2300 | E16: =E12*E14 -> 4510
A19: Per-Pop-Up Detail (4 events)
A20: Event | B20: Venue type | C20: Bear | D20: Base | E20: Bull | F20: Notes
A21: Pop-up #1 | B21: Friend office tower lobby (Wed) | C21: =C12 -> 300 | D21: =D12 -> 575 | E21: =E12 -> 1127.5 | F21: Lower foot traffic; office crowd
A22: Pop-up #2 | B22: Friend cafe carpark/patio (Sat) | C22: =C12 -> 300 | D22: =D12 -> 575 | E22: =E12 -> 1127.5 | F22: Weekend; established cafe traffic
A23: Pop-up #3 | B23: Creative space courtyard (Sun) | C23: =C12 -> 300 | D23: =D12 -> 575 | E23: =E12 -> 1127.5 | F23: Tests new audience
A24: Pop-up #4 | B24: Strongest venue repeat OR new format | C24: =C12 -> 300 | D24: =D12 -> 575 | E24: =E12 -> 1127.5 | F24: Repeat builds repeat-rate signal
B25: Sum check | C25: =SUM(C21:C24) -> 1200 | D25: =SUM(D21:D24) -> 2300 | E25: =SUM(E21:E24) -> 4510
A27: Note: each pop-up modelled at average per-event revenue. Real variance high — Pop-up #1 likely under, #2/#4 likely over.

Sheet 4. P1 Net Cash
A1: PHASE 1 NET CASH POSITION — Combined view
A2: Pulls from sheets 2 (Budget) and 3 (Revenue). Shows net burn after carboot revenue.
A4: Component | B4: Bear | C4: Base | D4: Bull | E4: Notes
A5: Phase 1 Cost (Total out-of-pocket) | B5: ='2. P1 Budget'!C56 -> 11200 | C5: ='2. P1 Budget'!D56 -> 17061 | D5: ='2. P1 Budget'!E56 -> 23740 | E5: Min=Bear, Max=Bull
A6: Less: Reusable equipment (carries to Phase 2) | B6: ='2. P1 Budget'!C57 -> 5430 | C6: ='2. P1 Budget'!D57 -> 7570 | D6: ='2. P1 Budget'!E57 -> 10440 | E6: Investment, not lost spend
A7: Phase 1 NET equipment burn | B7: =B5-B6 -> 5770 | C7: =C5-C6 -> 9491 | D7: =D5-D6 -> 13300 | E7: True cost lost in Phase 1
A9: Phase 1 Revenue (4 carboot pop-ups) | B9: ='3. P1 Revenue'!C16 -> 1200 | C9: ='3. P1 Revenue'!D16 -> 2300 | D9: ='3. P1 Revenue'!E16 -> 4510 | E9: From P1 Revenue sheet
A11: NET CASH POSITION after Phase 1 (revenue − net burn) | B11: =B9-B7 -> -4570 | C11: =C9-C7 -> -7191 | D11: =D9-D7 -> -8790 | E11: Negative = expected for validation phase
A13: Phase 1 Cash Recovery Rate (Revenue / Net Burn) | B13: =IFERROR(B9/B7,0) -> 0.20797227 | C13: =IFERROR(C9/C7,0) -> 0.24233484 | D13: =IFERROR(D9/D7,0) -> 0.33909774 | E13: >50% = strong validation pricing power
A15: Reading the result
A16: • Negative net cash after Phase 1 is EXPECTED. Phase 1 is validation, not revenue.
A17: • Net burn in v2 is HIGHER than v1 — your prep list (proper cart, branded banner, 4 drippers, certs) is ~RM 4–5K more than the lo-fi v1 estimate. Reusable equipment offsets most of this in Phase 2.
A18: • Cash Recovery Rate >50% = strong pricing power signal. <30% = revisit Phase 4 pricing.
A19: • The NET equipment burn (truly "lost") is much smaller than the out-of-pocket cost, because most equipment carries to Phase 2.

Sheet 5. P2 Capex
A1: PHASE 2 BUILD CAPEX — Reduced (cart and brand identity carry from Phase 1)
A2: Phase 2 launches once Phase 1 Decision Gate clears. Items already covered in Phase 1 are reduced or removed.
A4: # | B4: Line item | C4: Min | D4: Base | E4: Max | F4: Carry from P1? | G4: Notes
A5: 2.01 | B5: Cart upgrade/finish (cart base from Phase 1, finish + signage) | C5: 400 | D5: 800 | E5: 1500 | F5: Yes (base) | G5: Phase 1 cart upgraded for full menu; not full new cart
A6: 2.02 | B6: Espresso machine (1-group, used or new) | C6: 3000 | D6: 4500 | E6: 6500 | F6: No | G6: Used La Marzocco / ECM ~RM 4,500
A7: 2.03 | B7: Espresso grinder (Eureka / Niche) | C7: 1500 | D7: 1800 | E7: 2800 | F7: No | G7: Filter grinder = Phase 1 Comandante
A8: 2.04 | B8: Brewing tools — espresso accessories only (tamper, distrib, knockbox) | C8: 200 | D8: 350 | E8: 550 | F8: No | G8: V60s/Origami/scales/kettle from Phase 1
A9: 2.05 | B9: Initial green coffee inventory (top-up beyond P1 trip) | C9: 800 | D9: 1200 | E9: 1800 | F9: Partial | G9: P1 trip brought 5–8 kg; this is the top-up
A10: 2.06 | B10: Co-roasting first 2 months (CR KL) | C10: 800 | D10: 1200 | E10: 1800 | F10: No | G10: 1 session/wk × 8 weeks at RM 100–225/session
A11: 2.07 | B11: Brand photography day shoot | C11: 600 | D11: 900 | E11: 1300 | F11: No | G11: Brand identity already paid in P1 — only photo here
A12: 2.08 | B12: Packaging — cups, sleeves, bags first production run | C12: 800 | D12: 1000 | E12: 1500 | F12: No | G12: 1,000 units first run
A13: 2.09 | B13: Cold brew kegs + cold brew kit | C13: 200 | D13: 350 | E13: 500 | F13: No | G13: 5L mini-keg ×2
A14: 2.10 | B14: Marketing launch (boost, micro-influencer) | C14: 400 | D14: 600 | E14: 1000 | F14: No | G14: IG/TikTok boosted posts month 1
A15: 2.11 | B15: Soft-launch venue sublet (1–2 events) | C15: 200 | D15: 350 | E15: 600 | F15: No | G15: Friend cafe sublet
A16: 2.12 | B16: Cart consumables first month (milk, water, etc.) | C16: 300 | D16: 450 | E16: 700 | F16: No | G16: First-month operating
A17: 2.13 | B17: Equipment service / first-month maintenance reserve | C17: 100 | D17: 200 | E17: 350 | F17: No | G17: Backflush cleaner, gaskets, tools
A18: 2.14 | B18: Contingency (10% of itemised) | C18: =ROUND(0.1*SUM(C5:C17),0) -> 930 | D18: =ROUND(0.1*SUM(D5:D17),0) -> 1370 | E18: =ROUND(0.1*SUM(E5:E17),0) -> 2090 | F18: No | G18: Standard 10% buffer
B19: Phase 2 GROSS capex (before P1 carry-over credit) | C19: =SUM(C5:C18) -> 10230 | D19: =SUM(D5:D18) -> 15070 | E19: =SUM(E5:E18) -> 22990
B20: Less: Reusable equipment from Phase 1 (already paid) | C20: =-'2. P1 Budget'!C57 -> -5430 | D20: =-'2. P1 Budget'!D57 -> -7570 | E20: =-'2. P1 Budget'!E57 -> -10440
B21: PHASE 2 NET CAPEX (new spend in Phase 2) | C21: =C19+C20 -> 4800 | D21: =D19+D20 -> 7500 | E21: =E19+E20 -> 12550

Sheet 6. Combined Capex
A1: COMBINED CAPEX — Phase 1 + Phase 2 vs RM 15K Budget
A2: The honest "what does it really cost to launch KNNO?" view. v2 reflects your full prep list.
A4: Component | B4: Bear | C4: Base | D4: Bull | E4: Notes
A5: Phase 1 NET equipment burn (true cost lost) | B5: ='2. P1 Budget'!C58 -> 5770 | C5: ='2. P1 Budget'!D58 -> 9491 | D5: ='2. P1 Budget'!E58 -> 13300 | E5: Out-of-pocket less reusable equipment
A6: Phase 1 Reusable equipment (becomes Phase 2 capex) | B6: ='2. P1 Budget'!C57 -> 5430 | C6: ='2. P1 Budget'!D57 -> 7570 | D6: ='2. P1 Budget'!E57 -> 10440 | E6: Cart, drippers, grinder, kettle, scales, brand ID, banner, seats, tables
A7: Phase 2 NET capex (new spend after carry-over) | B7: ='5. P2 Capex'!C21 -> 4800 | C7: ='5. P2 Capex'!D21 -> 7500 | D7: ='5. P2 Capex'!E21 -> 12550 | E7: Espresso, photography, packaging, marketing, etc.
A9: TOTAL LAUNCH CAPEX (P1 burn + P1 reusable + P2 net) | B9: =B5+B6+B7 -> 16000 | C9: =C5+C6+C7 -> 24561 | D9: =D5+D6+D7 -> 36290 | E9: The honest number
A10: Less: Phase 1 carboot revenue offset | B10: =-'3. P1 Revenue'!C16 -> -1200 | C10: =-'3. P1 Revenue'!D16 -> -2300 | D10: =-'3. P1 Revenue'!E16 -> -4510 | E10: Carboot sales partially fund the launch
A11: NET LAUNCH CAPEX after carboot revenue | B11: =B9+B10 -> 14800 | C11: =C9+C10 -> 22261 | D11: =D9+D10 -> 31780 | E11: What you actually need in the bank
A13: Available capital (your RM 15K) | B13: 15000 | C13: 15000 | D13: 15000 | E13: Per the brief
A14: Surplus / (Shortfall) vs RM 15K | B14: =B12-B11 -> -14800 | C14: =C12-C11 -> -22261 | D14: =D12-D11 -> -31780 | E14: Negative = need more capital or trim
A15: % of capital used | B15: =B11/B12 -> #DIV/0! | C15: =C11/C12 -> #DIV/0! | D15: =D11/D12 -> #DIV/0! | E15: >100% = over-budget
A17: Funding Status (Base scenario)
A18: Status flag | B18: =IF(C14>=0,"OK — within budget",IF(C14>=-2000,"TIGHT — trim or top-up",IF(C14>=-5000,"SHORTFALL — need ~RM 2–5K more capital","SEVERE SHORTFALL — re-evaluate scope"))) -> SEVERE SHORTFALL — re-evaluate scope
A20: Trim Options (apply if base shows shortfall)
A21: Trim option | B21: Saves | C21: Trade-off
A22: Buy used espresso machine (vs new) | B22: ~RM 1,500–2,500 | C22: Quality risk; service network harder
A23: Cart with water pump but NO sink (use 5L water tank) | B23: ~RM 500–800 | C23: Less convenient cleanup at venue
A24: Defer espresso entirely until month 3 (manual brew launch) | B24: ~RM 4,500+ | C24: Possible if Phase 1 shows manual handles cup count
A25: Trim packaging first run from 1,000 to 500 units | B25: ~RM 400–600 | C25: More frequent reorders
A26: Defer brand photo shoot to month 2 | B26: ~RM 600 | C26: Use Phase 1 carboot photos as launch material
A27: Sole Prop instead of Sdn Bhd | B27: ~RM 900 | C27: Less liability protection; still legally OK for cart-format
A28: 3 V60s instead of 4 (skip Origami) | B28: ~RM 200 | C28: Lose process variety
A29: Foldable seats only — skip tables | B29: ~RM 300 | C29: Less customer dwell setup

Sheet 7. Decision Gate
A1: PHASE 1 → PHASE 2 DECISION GATE — Weighted Scoring
A2: Run after all 4 carboot pop-ups. Enter ACTUALS in BLUE column F. Score auto-classifies GO / HOLD / NO-GO.
A4: # | B4: Criterion | C4: Weight | D4: Target | E4: Direction | F4: Actual | G4: Score | H4: Notes
A5: G.1 | B5: Total cups served (across 4 pop-ups) | C5: 0.15 | D5: 200 | E5: higher | F5: 200 | G5: =IFERROR(MIN(F5/D5,1),0) -> 1 | H5: Bear=120 · Base=200 · Bull=280
A6: G.2 | B6: Stop-rate at unfamiliar venues (% of foot traffic) | C6: 0.15 | D6: 0.08 | E6: higher_pct | F6: 0.08 | G6: =IFERROR(MIN(F6/D6,1),0) -> 1 | H6: Strangers stopping; not friends
A7: G.3 | B7: Repeat faces named (came back 2+ times) | C7: 0.1 | D7: 12 | E7: higher | F7: 12 | G7: =IFERROR(MIN(F7/D7,1),0) -> 1 | H7: Critical leading indicator
A8: G.4 | B8: Avg ticket (RM/cup) | C8: 0.08 | D8: 13 | E8: higher_curr | F8: 13 | G8: =IFERROR(MIN(F8/D8,1),0) -> 1 | H8: Confirms RM 12+ price tolerance
A9: G.5 | B9: Cup quality score (% of cups ≥3/4 internal) | C9: 0.12 | D9: 0.75 | E9: higher_pct | F9: 0.75 | G9: =IFERROR(MIN(F9/D9,1),0) -> 1 | H9: Internal cupping during Phase 1
A10: G.6 | B10: Critical defects served (count) — INVERTED | C10: 0.08 | D10: 0 | E10: lower | F10: 0 | G10: =IF(F10=0,1,MAX(0,1-F10*0.5)) -> 1 | H10: Any > 0 reduces score; target = zero
A11: G.7 | B11: Founder enjoyment avg (1–10) | C11: 0.12 | D11: 7 | E11: higher | F11: 7 | G11: =IFERROR(MIN(F11/D11,1),0) -> 1 | H11: Burnout / sustainability check
A12: G.8 | B12: Sustainable workload — both could do 3 days/wk? (1=Yes, 0=No) | C12: 0.1 | D12: 1 | E12: binary | F12: 1 | G12: =IF(F12>=D12,1,0) -> 1 | H12: Honest answer
A13: G.9 | B13: Indonesian-roasted vs CR KL cup parity (1=parity, 0=not) | C13: 0.05 | D13: 1 | E13: binary | F13: 1 | G13: =IF(F13>=D13,1,0) -> 1 | H13: Validates Indonesia R&D approach
A14: G.10 | B14: QR scan rate per cup (% of customers) | C14: 0.05 | D14: 0.3 | E14: higher_pct | F14: 0.3 | G14: =IFERROR(MIN(F14/D14,1),0) -> 1 | H14: Validates funnel into bag sales / IG
B15: Weights sum check (must = 100%) | C15: =SUM(C5:C14) -> 1
B17: TOTAL WEIGHTED SCORE | G17: =SUMPRODUCT(C5:C14,G5:G14) -> 1
B19: DECISION | C19: =IF(G17>=0.85,"GO — proceed to Phase 2 with confidence",IF(G17>=0.7,"GO with cautions — address weakest criteria first",IF(G17>=0.55,"HOLD — re-test 2 weeks with adjusted variables","NO-GO — consider pivot to online-only / extended validation"))) -> GO — proceed to Phase 2 with confidence
B22: Threshold Reference
B23: ≥ 85% | C23: GO — proceed to Phase 2 with confidence
B24: 70–84% | C24: GO with cautions — address weakest criteria first
B25: 55–69% | C25: HOLD — re-test 2 weeks with adjusted variables
B26: < 55% | C26: NO-GO — consider pivot to online-only OR extend validation 4–6 weeks
B28: Diagnostic: Worst-Performing Criteria
B29: Lowest score | C29: =MIN(G5:G14) -> 1 | D29: Number of criteria below 50% | F29: =COUNTIF(G5:G14,"<0.5") -> 0
B31: Note: defaults are set to TARGETS so the workbook opens at "GO with confidence." Replace BLUE actuals with real measurements after Phase 1 pop-ups.

Sheet 8. P1 Risks
A1: PHASE 1 RISK REGISTER — Indonesia trip + Carboot specifics
A2: Likelihood (1–5) × Impact (1–5) = Score (out of 25). ≥15 = critical, 9–14 = high, 4–8 = medium, ≤3 = low.
A4: # | B4: Risk | C4: Likelihood (1–5) | D4: Impact (1–5) | E4: Score | F4: Mitigation | G4: Owner | H4: Status
A5: R.01 | B5: Producer cancels in-person visit at last minute | C5: 3 | D5: 4 | E5: =C5*D5 -> 12 | F5: Confirm in writing 14d ahead; backup producer; rental roastery as Plan B | G5: F1 | H5: Open
A6: R.02 | B6: Customs / personal import issue with roasted/green | C6: 2 | D6: 4 | E6: =C6*D6 -> 8 | F6: Verify MOH+Customs rules pre-flight; declare honestly; carry receipts; volume kept clearly personal | G6: F1 | H6: Open
A7: R.03 | B7: F1 illness during Indonesia trip | C7: 2 | D7: 5 | E7: =C7*D7 -> 10 | F7: Travel insurance; F2 pre-briefed on venue logistics; carboot can defer 1 wk | G7: Both | H7: Open
A8: R.04 | B8: Indonesian roastery quality inadequate (no curve logging, drum issues) | C8: 3 | D8: 4 | E8: =C8*D8 -> 12 | F8: Visit roastery before paying; rental roastery as Plan B; bring own thermometer/scale | G8: F1 | H8: Open
A9: R.05 | B9: Carboot venue cancellations (last-minute) | C9: 3 | D9: 3 | E9: =C9*D9 -> 9 | F9: 5–6 venue options; confirm 48h ahead; Plan B per event | G9: F2 | H9: Open
A10: R.06 | B10: Coffee cart fabrication delayed (pump/sink integration takes longer) | C10: 3 | D10: 4 | E10: =C10*D10 -> 12 | F10: Order cart Week -7; have backup folding-table fallback for first 1–2 pop-ups | G10: F2 | H10: Open
A11: R.07 | B11: Beans damaged/stale by time they reach MY | C11: 2 | D11: 4 | E11: =C11*D11 -> 8 | F11: Vacuum-pack within 24h of roast; ship within 5 days; cup test within 7 days | G11: F1 | H11: Open
A12: R.08 | B12: F2 burnout from solo work in MY weeks -6/-5 | C12: 4 | D12: 3 | E12: =C12*D12 -> 12 | F12: Pre-load tasks into Week -7; daily 15-min sync; no new commitments | G12: F2 | H12: Open
A13: R.09 | B13: DBKL Roving Hawker permit denied or delayed | C13: 3 | D13: 4 | E13: =C13*D13 -> 12 | F13: Submit application Week -8; use friend-cafe carparks (covered by their licence) as fallback for first pop-ups | G13: F2 | H13: Open
A14: R.10 | B14: Typhoid jab + food handling cert delays | C14: 2 | D14: 3 | E14: =C14*D14 -> 6 | F14: Book both founders in Week -8 (KKM clinics); typically 1 week turnaround | G14: Both | H14: Open
A15: R.11 | B15: Brand identity not delivered in time for banner | C15: 4 | D15: 3 | E15: =C15*D15 -> 12 | F15: Designer engaged Week -8 (one week earlier than original plan); brief is light (logo + 2 colours + type) | G15: F2 | H15: Open
A16: R.12 | B16: Equipment damage / loss during travel (Indonesia ↔ MY) | C16: 2 | D16: 3 | E16: =C16*D16 -> 6 | F16: Carry-on valuables; checked-baggage insurance; minimal equipment to/from Indonesia | G16: F1 | H16: Open
... A27: R.23 | B27: Public liability claim during carboot (slip, burn, allergy) | C27: 1 | D27: 5 | E27: =C27*D27 -> 5 | F27: Insurance from Week -8; ice/burn first aid kit; allergen disclosure on banner | G27: Both | H27: Open
B29: Risk Register Summary
B30: Total risks tracked | C30: =COUNTA(A5:A27) -> 23
B31: Critical risks (score ≥15) | C31: =COUNTIF(E5:E27,">=15") -> 1
B32: High risks (score 9–14) | C32: =COUNTIFS(E5:E27,">=9",E5:E27,"<=14") -> 13
B33: Medium risks (score 4–8) | C33: =COUNTIFS(E5:E27,">=4",E5:E27,"<=8") -> 8
B34: Low risks (score ≤3) | C34: =COUNTIF(E5:E27,"<=3") -> 1
B35: Aggregate risk exposure (sum of scores) | C35: =SUM(E5:E27) -> 215
B36: Average risk score | C36: =AVERAGE(E5:E27) -> 9.3478261

Sheet 9. P1 Sensitivity
A1: PHASE 1 SENSITIVITY — Carboot Revenue (cups × ticket × 4 events)
A2: What-if matrix: cups served per pop-up × avg ticket = total Phase 1 revenue. Highlight = % of Phase 1 cost recovered.
A4: Phase 1 base cost (out-of-pocket, RM): | B4: ='2. P1 Budget'!D56 -> 17061
A5: Number of pop-ups: | B5: 4
A7: REVENUE MATRIX (RM) | B7: Avg ticket (RM/cup) →
A8: Cups per pop-up ↓ | B8: 10 | C8: 11 | D8: 12 | E8: 13 | F8: 14 | G8: 15 | H8: 16 | I8: 18
A9: 15 | B9: =$A9*B$8*$B5 -> 600 | C9: =$A9*C$8*$B5 -> 660 | D9: =$A9*D$8*$B5 -> 720 | E9: =$A9*E$8*$B5 -> 780 | F9: =$A9*F$8*$B5 -> 840 | G9: =$A9*G$8*$B5 -> 900 | H9: =$A9*H$8*$B5 -> 960 | I9: =$A9*I$8*$B5 -> 1080
A10: 20 | B10: =$A10*B$8*$B5 -> 800 | C10: =$A10*C$8*$B5 -> 880 | D10: =$A10*D$8*$B5 -> 960 | E10: =$A10*E$8*$B5 -> 1040 | F10: =$A10*F$8*$B5 -> 1120 | G10: =$A10*G$8*$B5 -> 1200 | H10: =$A10*H$8*$B5 -> 1280 | I10: =$A10*I$8*$B5 -> 1440
A11: 25 | B11: =$A11*B$8*$B5 -> 1000 | C11: =$A11*C$8*$B5 -> 1100 | D11: =$A11*D$8*$B5 -> 1200 | E11: =$A11*E$8*$B5 -> 1300 | F11: =$A11*F$8*$B5 -> 1400 | G11: =$A11*G$8*$B5 -> 1500 | H11: =$A11*H$8*$B5 -> 1600 | I11: =$A11*I$8*$B5 -> 1800
A12: 30 | B12: =$A12*B$8*$B5 -> 1200 | C12: =$A12*C$8*$B5 -> 1320 | D12: =$A12*D$8*$B5 -> 1440 | E12: =$A12*E$8*$B5 -> 1560 | F12: =$A12*F$8*$B5 -> 1680 | G12: =$A12*G$8*$B5 -> 1800 | H12: =$A12*H$8*$B5 -> 1920 | I12: =$A12*I$8*$B5 -> 2160
A13: 35 | B13: =$A13*B$8*$B5 -> 1400 | C13: =$A13*C$8*$B5 -> 1540 | D13: =$A13*D$8*$B5 -> 1680 | E13: =$A13*E$8*$B5 -> 1820 | F13: =$A13*F$8*$B5 -> 1960 | G13: =$A13*G$8*$B5 -> 2100 | H13: =$A13*H$8*$B5 -> 2240 | I13: =$A13*I$8*$B5 -> 2520
A14: 40 | B14: =$A14*B$8*$B5 -> 1600 | C14: =$A14*C$8*$B5 -> 1760 | D14: =$A14*D$8*$B5 -> 1920 | E14: =$A14*E$8*$B5 -> 2080 | F14: =$A14*F$8*$B5 -> 2240 | G14: =$A14*G$8*$B5 -> 2400 | H14: =$A14*H$8*$B5 -> 2560 | I14: =$A14*I$8*$B5 -> 2880
A15: 45 | B15: =$A15*B$8*$B5 -> 1800 | C15: =$A15*C$8*$B5 -> 1980 | D15: =$A15*D$8*$B5 -> 2160 | E15: =$A15*E$8*$B5 -> 2340 | F15: =$A15*F$8*$B5 -> 2520 | G15: =$A15*G$8*$B5 -> 2700 | H15: =$A15*H$8*$B5 -> 2880 | I15: =$A15*I$8*$B5 -> 3240
A16: 50 | B16: =$A16*B$8*$B5 -> 2000 | C16: =$A16*C$8*$B5 -> 2200 | D16: =$A16*D$8*$B5 -> 2400 | E16: =$A16*E$8*$B5 -> 2600 | F16: =$A16*F$8*$B5 -> 2800 | G16: =$A16*G$8*$B5 -> 3000 | H16: =$A16*H$8*$B5 -> 3200 | I16: =$A16*I$8*$B5 -> 3600
A17: 60 | B17: =$A17*B$8*$B5 -> 2400 | C17: =$A17*C$8*$B5 -> 2640 | D17: =$A17*D$8*$B5 -> 2880 | E17: =$A17*E$8*$B5 -> 3120 | F17: =$A17*F$8*$B5 -> 3360 | G17: =$A17*G$8*$B5 -> 3600 | H17: =$A17*H$8*$B5 -> 3840 | I17: =$A17*I$8*$B5 -> 4320
A18: 70 | B18: =$A18*B$8*$B5 -> 2800 | C18: =$A18*C$8*$B5 -> 3080 | D18: =$A18*D$8*$B5 -> 3360 | E18: =$A18*E$8*$B5 -> 3640 | F18: =$A18*F$8*$B5 -> 3920 | G18: =$A18*G$8*$B5 -> 4200 | H18: =$A18*H$8*$B5 -> 4480 | I18: =$A18*I$8*$B5 -> 5040
A19: 80 | B19: =$A19*B$8*$B5 -> 3200 | C19: =$A19*C$8*$B5 -> 3520 | D19: =$A19*D$8*$B5 -> 3840 | E19: =$A19*E$8*$B5 -> 4160 | F19: =$A19*F$8*$B5 -> 4480 | G19: =$A19*G$8*$B5 -> 4800 | H19: =$A19*H$8*$B5 -> 5120 | I19: =$A19*I$8*$B5 -> 5760
A21: Legend:
A22: Green | B22: Carboot revenue ≥ Phase 1 base cost (full recovery)
A23: Yellow | B23: Partial recovery (60–99% of Phase 1 cost)
A24: Red | B24: Low recovery (<60% of Phase 1 cost)
A26: Reading the matrix
A27: • Phase 1 cost is now ~RM 8–12K (your prep list). Full revenue recovery requires ~80 cups × RM 18+ across 4 pop-ups — not realistic at carboot prices.
A28: • Phase 1 is NOT designed to break even. The matrix shows whether revenue covers the OPS cost of 1C (~RM 1K), not the equipment investment.
A29: • GREEN cells signal Phase 4 (Public Launch) economics will likely beat the optimistic scenario in [[09-Financial Projections (Conservative)]].
A30: • Most of the Phase 1 spend is RECOVERABLE EQUIPMENT (carries to Phase 2) — the true "lost" cost is much smaller.

Sheet 10. Cash Tracker
A1: WEEK-BY-WEEK CASH TRACKER (Base scenario, v2)
A2: Running cash position from Week -8 through Week +12. Updated for v2 prep list (higher Phase 1 outflow).
A4: Starting capital (RM): | B4: 15000
A6: Week | B6: Date range | C6: Activity | D6: Inflow | E6: Outflow | F6: Net cash | G6: Notes
A7: W -8 | B7: May 4–10 | C7: Foundation: legal, brand brief sent, certs booked, accounts | D7: 0 | E7: 600 | F7: =B4+D7-E7 -> 14400 | G7: Bank acct, domain, typhoid jab + food handler course bookings
A8: W -7 | B8: May 11–17 | C8: Foundation: suppliers, Indonesia trip booked, cart ordered, designer engaged | D8: 0 | E8: 4500 | F8: =F7+D8-E8 -> 9900 | G8: Indonesia flight + cart deposit (RM 1.5K) + designer deposit + permit fees
A9: W -6 | B9: May 18–24 | C9: Indonesia week 1 + MY parallel work | D9: 0 | E9: 3500 | F9: =F8+D9-E9 -> 6400 | G9: F1 in Indonesia (accom, food, roastery, green) + cart final payment + drippers/grinder/kettle
A10: W -5 | B10: May 25–31 | C10: Indonesia week 2 + Carboot Pop-up #1 | D10: 700 | E10: 2200 | F10: =F9+D10-E10 -> 4900 | G10: F1 returns; Pop-up #1 small office crowd; banner printed; remaining equipment
A11: W -4 | B11: Jun 1–7 | C11: Carboot Pop-ups #2, #3, #4 + Decision Gate | D11: 1900 | E11: 800 | F11: =F10+D11-E11 -> 6000 | G11: 3 pop-ups ~50 cups avg × RM 13
A12: W -3 | B12: Jun 8–14 | C12: Phase 2 Build: espresso machine + grinder + green top-up | D12: 0 | E12: 6500 | F12: =F11+D12-E12 -> -500 | G12: Major Phase 2 capex item — espresso + grinder
A13: W -2 | B13: Jun 15–21 | C13: Phase 2 Build: 1st production roast, packaging, photo shoot | D13: 0 | E13: 2200 | F13: =F12+D13-E13 -> -2700 | G13: Co-roasting + packaging first run + photography
A14: W -1 | B14: Jun 22–28 | C14: Phase 2 Build: cart finish, drill, soft launch booking | D14: 0 | E14: 1500 | F14: =F13+D14-E14 -> -4200 | G14: Cart finishing/upgrade + sundries + soft-launch venue + insurance balance
A15: W 0 | B15: Jun 29 – Jul 5 | C15: PHASE 3: Soft launch + Phase 4 launch week | D15: 700 | E15: 400 | F15: =F14+D15-E15 -> -3900 | G15: Soft launch invitee revenue (40 cups × RM 16)
A16: W +1 | B16: Jul 6–12 | C16: PHASE 4: Public launch — 1st pop-up | D16: 720 | E16: 500 | F16: =F15+D16-E16 -> -3680 | G16: ~45 cups × RM 16; venue + roast
A17: W +2 | B17: Jul 13–19 | C17: 2nd public pop-up + online drop launch | D17: 1100 | E17: 550 | F17: =F16+D17-E17 -> -3130 | G17: Cup + bag online drop
A18: W +3 | B18: Jul 20–26 | C18: 3rd & 4th pop-ups, weekly review settled | D18: 1500 | E18: 600 | F18: =F17+D18-E18 -> -2230 | G18: Cadence locked
A19: W +4 | B19: Jul 27 – Aug 2 | C19: Continued cadence | D19: 1500 | E19: 600 | F19: =F18+D19-E19 -> -1330
A20: W +5 | B20: Aug 3–9 | C20: Aug rhythm | D20: 1600 | E20: 700 | F20: =F19+D20-E20 -> -430 | G20: 2nd signature lot launch
A21: W +6 | B21: Aug 10–16 | D21: 1700 | E21: 700 | F21: =F20+D21-E21 -> 570
A22: W +7 | B22: Aug 17–23 | D22: 1700 | E22: 700 | F22: =F21+D22-E22 -> 1570
A23: W +8 | B23: Aug 24–30 | C23: Quarterly pre-mortem | D23: 1700 | E23: 800 | F23: =F22+D23-E23 -> 2470 | G23: Insurance renewal + service
A24: W +9 | B24: Aug 31 – Sep 6 | D24: 1800 | E24: 700 | F24: =F23+D24-E24 -> 3570
A25: W +10 | B25: Sep 7–13 | D25: 1800 | E25: 700 | F25: =F24+D25-E25 -> 4670
A26: W +11 | B26: Sep 14–20 | D26: 1800 | E26: 800 | F26: =F25+D26-E26 -> 5670 | G26: Aceh harvest forward-buy starts
A27: W +12 | B27: Sep 21–27 | D27: 1900 | E27: 800 | F27: =F26+D27-E27 -> 6770
C28: Totals (W -8 → W +12) | D28: =SUM(D7:D27) -> 22120 | E28: =SUM(E7:E27) -> 30350 | F28: =F27 -> 6770
C30: Lowest cash position (cash floor): | F30: =MIN(F7:F27) -> -4200
C31: Week of cash floor: | F31: =INDEX(A7:A27,MATCH(MIN(F7:F27),F7:F27,0)) -> W -1
A33: Cash position colour key: GREEN >RM 3,000 (healthy) · YELLOW RM 0–3,000 (caution) · RED <RM 0 (CRITICAL — out of cash)
A34: Note: with v2 prep list, Phase 1 outflow concentrates in Weeks -7 to -3. Cash floor likely Week -3 (RM ~3K range). If RED appears, you need ~RM 5–8K more capital OR aggressive trim.
